Workbook

Sheet Sheet1
A1: CP功能设置说明
A3: 萝卜设置 | B3: 参数名称 | C3: 中文描述 | D3: 备注说明 | E3: 设备说明 | F3: 最小值 | G3: 最大值 | H3: 步长 | I3: 范大 數值
A4: 开始菜单 | B4: HyundaiCameraSCC | C4: 现代：摄像头 SCC (0) | D4: 1: 连接 SCC 的 CAN 线到摄像头，2: 同步定速状态，3: 原厂长控，不是用摄像头实现 SCC 的均设置为 0 | E4: （本页菜单不要调整，对本车型请保持默认设置，不要进行修改） | F4: 0 | G4: 3 | H4: 1 | I4: =VLOOKUP(B4,'CP設定檔(2023 IONIQ5)_backup'!A:B,2,FALSE) -> 2
B5: CanfdHDA2 | C5: CANFD: HDA2 模式 | D5: 1:HDA2, 2:HDA2 + 盲点监测，一般非 CanFD 车型设置为 0 | F5: 0 | G5: 2 | H5: 1 | I5: =VLOOKUP(B5,'CP設定檔(2023 IONIQ5)_backup'!A:B,2,FALSE) -> 2
B6: EnableRadarTracks | C6: 启用雷达追踪 (1) | D6: 1: 启用雷达追踪，-1,2: 禁用 (始终使用 HKG SCC 雷达)，胜达设置为 1, 改变值后需要重启车辆 | F6: -1 | G6: 3 | H6: 1 | I6: =VLOOKUP(B6,'CP設定檔(2023 IONIQ5)_backup'!A:B,2,FALSE) -> 1
B7: EnableEscc | C7: 启用 ESCC (1) | D7: 1: 启用 ESCC, 0: 禁用，改变值后需要重启车辆 | F7: 0 | G7: 1 | H7: 1 | I7: =VLOOKUP(B7,'CP設定檔(2023 IONIQ5)_backup'!A:B,2,FALSE) -> #N/A
B8: AutoCruiseControl | C8: 自动巡航控制 (0) | D8: 自动巡航总开关，0 - 关，>1 开，>1 softmode1 否则 softmode2 | F8: 0 | G8: 3 | H8: 1 | I8: =VLOOKUP(B8,'CP設定檔(2023 IONIQ5)_backup'!A:B,2,FALSE) -> 0
B9: CruiseOnDist | C9: 定速：自动开启距离 (0cm) | D9: 当油门 / 刹车未踩下时，前车靠近自动开启定速 | F9: 0 | G9: 2500 | H9: 50 | I9: =VLOOKUP(B9,'CP設定檔(2023 IONIQ5)_backup'!A:B,2,FALSE) -> 400
B10: AutoEngage | C10: 车辆启动时自动开启的功能 | D10: 1: 车道保持启用，2: 车道保持 + 定速启用 | F10: 0 | G10: 2 | H10: 1 | I10: =VLOOKUP(B10,'CP設定檔(2023 IONIQ5)_backup'!A:B,2,FALSE) -> 1
B11: AutoGasTokSpeed | C11: 轻踩油门开启巡航的速度 | D11: 当车速大于此速度时，轻点油门巡航速度加 10，也可自动开启巡航，前提是 ' 自动巡航控制 ' 必须要打开 | F11: 0 | G11: 200 | H11: 5 | I11: =VLOOKUP(B11,'CP設定檔(2023 IONIQ5)_backup'!A:B,2,FALSE) -> 80
B12: SpeedFromPCM | C12: 从 PCM 读取定速速度 (2) | D12: 丰田必须设为 1, 本田设为 3，默认为 2 | F12: 0 | G12: 3 | H12: 1 | I12: =VLOOKUP(B12,'CP設定檔(2023 IONIQ5)_backup'!A:B,2,FALSE) -> 0
B13: SoundVolumeAdjust | C13: 提示音音量 (100%) | D13: - | F13: 5 | G13: 200 | H13: 5 | I13: =VLOOKUP(B13,'CP設定檔(2023 IONIQ5)_backup'!A:B,2,FALSE) -> 80
B14: SoundVolumeAdjustEngage | C14: 接管提示音音量 (100%) | D14: - | F14: 5 | G14: 200 | H14: 5 | I14: =VLOOKUP(B14,'CP設定檔(2023 IONIQ5)_backup'!A:B,2,FALSE) -> 100
B15: MaxTimeOffroadMin | C15: 熄屏时间 (分钟) | D15: - | F15: 1 | G15: 600 | H15: 10 | I15: =VLOOKUP(B15,'CP設定檔(2023 IONIQ5)_backup'!A:B,2,FALSE) -> 60
B16: EnableConnect | C16: 启用远程连接 | D16: 您的设备可能会被 Comma 封禁 | F16: 0 | G16: 2 | H16: 1 | I16: =VLOOKUP(B16,'CP設定檔(2023 IONIQ5)_backup'!A:B,2,FALSE) -> 0
... B27: IsLdwsCar | C27: 是否 LDWS 车型 | D27: - | F27: 0 | G27: 1 | H27: 1 | I27: =VLOOKUP(B27,'CP設定檔(2023 IONIQ5)_backup'!A:B,2,FALSE) -> 1
A28: 巡航菜单 | B28: TFollowGap1 | C28: 跟车时间 GAP1 (110) x0.01s | D28: fast模式跟车时距 | E28: 时距的简单理解就是多少秒后到达前方位置，配合驾驶模式使用 | F28: 70 | G28: 300 | H28: 5 | I28: =VLOOKUP(B28,'CP設定檔(2023 IONIQ5)_backup'!A:B,2,FALSE) -> 75
B29: TFollowGap2 | C29: 跟车时间 GAP2 (120) x0.01s | D29: norm模式跟车时距 | F29: 70 | G29: 300 | H29: 5 | I29: =VLOOKUP(B29,'CP設定檔(2023 IONIQ5)_backup'!A:B,2,FALSE) -> 85
B30: TFollowGap3 | C30: 跟车时间 GAP3 (160) x0.01s | D30: safe模式跟车时距 | F30: 70 | G30: 300 | H30: 5 | I30: =VLOOKUP(B30,'CP設定檔(2023 IONIQ5)_backup'!A:B,2,FALSE) -> 100
B31: TFollowGap4 | C31: 跟车时间 GAP4 (180) x0.01s | D31: eco模式跟车时距 | F31: 70 | G31: 300 | H31: 5 | I31: =VLOOKUP(B31,'CP設定檔(2023 IONIQ5)_backup'!A:B,2,FALSE) -> 120
B32: DynamicTFollow | C32: 动态跟车 GAP 控制 | D32: - | E32: 这个跟车不稳定，设置0 | F32: 0 | G32: 100 | H32: 5 | I32: =VLOOKUP(B32,'CP設定檔(2023 IONIQ5)_backup'!A:B,2,FALSE) -> 50
B33: DynamicTFollowLC | C33: 动态跟车 GAP 控制 (变道) | D33: - | E33: 变道时的前车临时时距 | F33: 0 | G33: 100 | H33: 5 | I33: =VLOOKUP(B33,'CP設定檔(2023 IONIQ5)_backup'!A:B,2,FALSE) -> 100
B34: MyDrivingMode | C34: 驾驶模式选择 | D34: 1: eco，2:safe，3: norm，4: fast | E34: 使用场景建议 Eco: 城市驾驶、注重燃油经济性、长途巡航、跟车稳定缓慢 Safe: 复杂交通、恶劣天气、新驾驶员、跟车稳定缓慢 Normal: 日常高速驾驶、平衡需求、跟车距离略近 fast: 空旷道路、经验丰富的驾驶员、运动驾驶、这个模式不识别红绿灯、自己知道在干什么 | F34: 1 | G34: 4 | H34: 1 | I34: =VLOOKUP(B34,'CP設定檔(2023 IONIQ5)_backup'!A:B,2,FALSE) -> 3
B35: MyDrivingModeAuto | C35: 驾驶模式自动 | D35: 0: 关闭，1: 开启 (仅普通模式) | E35: 自动模式检测仅在 Safe 和 Normal 之间切换，不会自动切换到 Eco 或 High 模式。状态切换规则 进入 Safe 模式（拥堵判定） 前车距离 ≤ 12m 且前车速度 ≤ 2 km/h 返回 Normal 模式（畅通判定） 满足以下任一条件： 前车加速度 > 1.5 m/s² 本车速度 > 35 km/h 前车距离 ≥ 200m | F35: 0 | G35: 1 | H35: 1 | I35: =VLOOKUP(B35,'CP設定檔(2023 IONIQ5)_backup'!A:B,2,FALSE) -> 1
B36: TrafficLightDetectMode | C36: 红绿灯检测模式 | D36: 0: 无，1: 仅停止，2: 停走模式 | F36: 0 | G36: 2 | H36: 1 | I36: =VLOOKUP(B36,'CP設定檔(2023 IONIQ5)_backup'!A:B,2,FALSE) -> 2
A37: 导航菜单 | B37: RoadType | C37: 手动设置道路类型 (-1) | D37: -2: 从导航获取 (>=85 快速路，>=100 高速，公路类型由导航决定),-1: 自动 (<85km/h 公路，>=85 快速路，>=100 高速)，0: 高速 (无应急车道) 1: 高速 (有应急车道), >=2: 其它道路 | E37: 根据车速、限速来分辨当前什么路 | F37: -10 | G37: 100 | H37: 1 | I37: =VLOOKUP(B37,'CP設定檔(2023 IONIQ5)_backup'!A:B,2,FALSE) -> #N/A
B38: SameSpiCamFilter | C38: 过滤相同测速数据 (1) | D38: 0: 关闭，1: 打开 | E38: 不相干的菜单 | F38: 0 | G38: 1 | H38: 1 | I38: =VLOOKUP(B38,'CP設定檔(2023 IONIQ5)_backup'!A:B,2,FALSE) -> #N/A
B39: StockBlinkerCtrl | C39: 外接控制原车转向拔杆 (0) | D39: 0: 关闭，1: 打开 | F39: 0 | G39: 1 | H39: 1 | I39: =VLOOKUP(B39,'CP設定檔(2023 IONIQ5)_backup'!A:B,2,FALSE) -> #N/A
B40: ExtBlinkerCtrlTest | C40: 外接控制器自检 (1) | D40: 0: 关闭，1: 打开 | F40: 0 | G40: 1 | H40: 1 | I40: =VLOOKUP(B40,'CP設定檔(2023 IONIQ5)_backup'!A:B,2,FALSE) -> #N/A
B41: BlinkerMode | C41: 手动打灯控制模式 (0) | D41: 0: 自动，1: 仅变道 | F41: 0 | G41: 1 | H41: 1 | I41: =VLOOKUP(B41,'CP設定檔(2023 IONIQ5)_backup'!A:B,2,FALSE) -> #N/A
B42: LaneStabTime | C42: 车道数稳定时间 (10x0.1s) | D42: 当检测车道数稳定时间超过设定值后，则认为已经稳定，单位为 0.1 秒 | E42: 系统检测车道时超过设定值x0.1秒时认定车道稳定 | F42: 5 | G42: 100 | H42: 1 | I42: =VLOOKUP(B42,'CP設定檔(2023 IONIQ5)_backup'!A:B,2,FALSE) -> #N/A
B43: BsdDelayTime | C43: 后盲区有车延时 (20x0.1s) | D43: 当后盲区有车信号消失后，经过延时的秒数后允许变道 | E43: 时间为设定值x0.1秒 | F43: 0 | G43: 100 | H43: 1 | I43: =VLOOKUP(B43,'CP設定檔(2023 IONIQ5)_backup'!A:B,2,FALSE) -> #N/A
B44: SideBsdDelayTime | C44: 侧前方有车延时 (20x0.1s) | D44: 当侧前方有车信号消失后，经过延时的秒数后允许变道 | E44: 时间为设定值x0.1秒 | F44: 0 | G44: 100 | H44: 1 | I44: =VLOOKUP(B44,'CP設定檔(2023 IONIQ5)_backup'!A:B,2,FALSE) -> #N/A
B45: SideRelDistTime | C45: 侧前方有车变道相对距离 | D45: 当与侧前方车辆相对距离小于本车速度 x 时间时不允许变道，单位 0.1 秒 | E45: 理解为越小越容易变道 | F45: 0 | G45: 50 | H45: 1 | I45: =VLOOKUP(B45,'CP設定檔(2023 IONIQ5)_backup'!A:B,2,FALSE) -> #N/A
B46: SidevRelDistTime | C46: 侧前方有车变道等效距离 | D46: 侧前方车辆速度 x3 + 相对距离小于本车速度 x (时间 + 3) 时，不允许变道，单位 0.1 秒 | E46: 理解为越小越容易变道 | F46: 0 | G46: 50 | H46: 1 | I46: =VLOOKUP(B46,'CP設定檔(2023 IONIQ5)_backup'!A:B,2,FALSE) -> #N/A
B47: SideRadarMinDist | C47: 侧面最小雷达距离 (0m) | D47: 在左右两侧的车道上，忽略小于此雷达探测距离的车辆，单位为 0.1m | E47: 侧面设置无效 | F47: -50 | G47: 100 | H47: 1 | I47: =VLOOKUP(B47,'CP設定檔(2023 IONIQ5)_backup'!A:B,2,FALSE) -> #N/A
B48: AutoForkDistOffsetH | C48: H 提前靠边行驶距离 (1000m) | D48: 在距离匝道口多少米时开始变道到最侧面车道，设置为 0 则不提前变道 | E48: 高速道路相关设置 | F48: 0 | G48: 2000 | H48: 5 | I48: =VLOOKUP(B48,'CP設定檔(2023 IONIQ5)_backup'!A:B,2,FALSE) -> #N/A
B49: AutoEnTurnNewLaneTimeH | C49: H 继续变道新车道时间 (0s) | D49: 车辆已在最侧边车道，若新车道出现的时间超过设置值后允许再次变道，推荐值 20 秒，0 关闭 | E49: 高速道路相关设置 | F49: 0 | G49: 120 | H49: 1 | I49: =VLOOKUP(B49,'CP設定檔(2023 IONIQ5)_backup'!A:B,2,FALSE) -> #N/A
B50: AutoDoForkDecalDistH | C50: H 进匝道减速距离偏移 (50m) | D50: 在距离匝道口多少米时开始减速，软件根据速度计算的距离加上此偏移为实际距离 | E50: 高速道路相关设置 | F50: 0 | G50: 500 | H50: 5 | I50: =VLOOKUP(B50,'CP設定檔(2023 IONIQ5)_backup'!A:B,2,FALSE) -> #N/A
B51: AutoDoForkBlinkerDistH | C51: H 进匝道打灯距离偏移 (30m) | D51: 在距离匝道口多少米时开始打转身灯准备变道，但不是一定会立即变道，还需要等匝道出现的条件成立，软件根据速度计算的距离加上此偏移为实际距离 | E51: 高速道路相关设置 | F51: 0 | G51: 200 | H51: 2 | I51: =VLOOKUP(B51,'CP設定檔(2023 IONIQ5)_backup'!A:B,2,FALSE) -> #N/A
...

Sheet CP設定檔(2023 IONIQ5)_backup
A1: AChangeCostStarting | B1: 10
A2: ActivateCruiseAfterBrake | B2: 0
A3: AdjustLaneOffset | B3: 0
A4: ApplyModelSpeed | B4: 60
A5: AutoCruiseControl | B5: 0
A6: AutoCurveSpeedAggressiveness | B6: 100
A7: AutoCurveSpeedFactor | B7: 85
A8: AutoCurveSpeedLowerLimit | B8: 35
A9: AutoEngage | B9: 1
A10: AutoGasSyncSpeed | B10: 0
A11: AutoGasTokSpeed | B11: 80
A12: AutoNaviCountDownMode | B12: 2
... A31: CarrotCruiseDecel | B31: 1
A32: CarSelected3 | B32: Hyundai Ioniq 5 (Southeast Asia and Europe only) 2022-24
A33: CompletedTrainingVersion | B33: 0.2.0
A34: CruiseButtonLongDelay | B34: 40
A35: CruiseButtonMode | B35: 1
A36: CruiseButtonTest1 | B36: 8
A37: CruiseButtonTest2 | B37: 30
A38: CruiseButtonTest3 | B38: 1
A39: CruiseEcoControl | B39: 2
A40: CruiseMaxVals0 | B40: 155
A41: CruiseMaxVals1 | B41: 165
A42: CruiseMaxVals2 | B42: 140
A43: CruiseMaxVals3 | B43: 130
A44: CruiseMaxVals4 | B44: 110
A45: CruiseMaxVals5 | B45: 95
... A62: DisableMinSteerSpeed | B62: 1
A63: DisengageOnAccelerator | B63: FALSE
A64: DynamicTFollow | B64: 50
A65: DynamicTFollowLC | B65: 100
A66: EnableConnect | B66: 0
A67: EnableCornerRadar | B67: 2
A68: EnableRadarTracks | B68: 1
A69: EnableSpeedTF | B69: 20
A70: EVTable | B70: FALSE
A71: GsmMetered | B71: TRUE
A72: HapticFeedbackWhenSpeedCamera | B72: 0
A73: HardwareC3xLite | B73: 0
A74: HasAcceptedTerms | B74: 2
...
